The following values were not passed to `accelerate launch` and had defaults used instead:
	`--num_processes` was set to a value of `1`
	`--num_machines` was set to a value of `1`
	`--dynamo_backend` was set to a value of `'no'`
To avoid this warning pass in values for each of the problematic parameters or run `accelerate config`.
/opt/conda/bin/python: can't open file '/workspace/emojifusion/scripts/3rd/diffusers/examples/text_to_image/train_text_to_image_lora.py': [Errno 2] No such file or directory
Traceback (most recent call last):
  File "/opt/conda/bin/accelerate", line 8, in <module>
    sys.exit(main())
  File "/opt/conda/lib/python3.10/site-packages/accelerate/commands/accelerate_cli.py", line 47, in main
    args.func(args)
  File "/opt/conda/lib/python3.10/site-packages/accelerate/commands/launch.py", line 986, in launch_command
    simple_launcher(args)
  File "/opt/conda/lib/python3.10/site-packages/accelerate/commands/launch.py", line 628, in simple_launcher
    raise subprocess.CalledProcessError(returncode=process.returncode, cmd=cmd)
subprocess.CalledProcessError: Command '['/opt/conda/bin/python', '3rd/diffusers/examples/text_to_image/train_text_to_image_lora.py', '--pretrained_model_name_or_path=runwayml/stable-diffusion-v1-5', '--dataset_name=../data/emojis/emojisdescr', '--dataloader_num_workers=8', '--resolution=512', '--center_crop', '--random_flip', '--train_batch_size=1', '--gradient_accumulation_steps=4', '--max_train_steps=5000', '--learning_rate=1e-04', '--max_grad_norm=1', '--lr_scheduler=cosine', '--lr_warmup_steps=0', '--output_dir=weights/finetuned_emojis_2', '--checkpointing_steps=500', '--validation_prompt=A face of evil gnome.', '--seed=1337']' returned non-zero exit status 2.
